<?xml version="1.0" encoding="utf-8"?>
<mujoco model="robot_2">
  <compiler angle="radian" inertiafromgeom="true" coordinate="local" />
  <option timestep="0.01" gravity="0 0 -9.81" integrator="RK4" />
  <size njmax="500" nconmax="100" />
  <worldbody>
    <geom name="floor" type="plane" size="10 10 0.1" pos="0 0 0" rgba="0.8 0.9 0.9 1" />
    <light name="light1" pos="0 0 3" dir="0 0 -1" directional="true" />
    <body name="robot_root" pos="0 0 0.5" quat="1 0 0 0">
      <body name="G">
        <geom name="G_vis0" type="box" rgba="0.37254901960784315 0.5019607843137255 0.8352941176470589 1.0" contype="1" conaffinity="1" pos="0.0 0.0 0.0" quat="1.0 0.0 0.0 0.0" size="0.02 0.02 0.02" />
        <inertial pos="0.0 0.0 0.0" mass="0.010434248887524934" diaginertia="2.782466370006649e-06 2.782466370006649e-06 2.782466370006649e-06" />
        <body name="L6" pos="0.0 0.0 0.0" quat="0.05740672490601135 5.76162120280019e-17 0.9983508741597643 5.76162120280019e-17">
          <joint name="Main_ground" type="hinge" axis="0 1 0" range="-3.141592653589793 3.141592653589793" damping="0.1" />
          <geom name="L6_vis0" type="box" rgba="0.1568627450980392 0.42745098039215684 0.8 1.0" contype="1" conaffinity="1" pos="8.008223628835724e-17 0.0 0.17012128026793125" quat="1.0 0.0 0.0 0.0" size="0.009999999776482582 0.009999999776482582 0.16012128049144866" />
          <geom name="L6_vis1" type="box" rgba="0.1568627450980392 0.42745098039215684 0.8 1.0" contype="1" conaffinity="1" pos="-0.024327343078314124 0.0 0.1071764065687967" quat="0.9937790602856788 0.0 -0.1113695619894114 0.0" size="0.009999999776482582 0.009999999776482582 0.09990269239368224" />
          <geom name="L6_vis2" type="box" rgba="0.1568627450980392 0.42745098039215684 0.8 1.0" contype="1" conaffinity="1" pos="-0.024327343078314044 0.0 0.27729768683672795" quat="0.18335811086497625 -4.896677205692733e-17 -0.9830461856800152 4.896677205692733e-17" size="0.009999999776482582 0.009999999776482582 0.05748241827629619" />
          <inertial pos="-0.01622 0.0 0.18487" mass="0.16173688658481772" diaginertia="0.02191345675655164 0.0223761845142554 0.0004735102163274033" />
          <body name="L7" pos="1.6016447257671449e-16 0.0 0.3402425605358625" quat="0.9867473260080689 0.0 0.1622643356253175 0.0">
            <joint name="Main_knee" type="hinge" axis="0 1 0" range="-3.141592653589793 3.141592653589793" damping="0.1" />
            <geom name="L7_vis0" type="box" rgba="0.5176470588235295 0.5843137254901961 0.8705882352941177 1.0" contype="1" conaffinity="1" pos="-6.938893903907228e-18 0.0 0.028385080257945366" quat="1.0 0.0 0.0 0.0" size="0.009999999776482582 0.009999999776482582 0.018385080481462784" />
            <geom name="L7_vis1" type="box" rgba="0.5176470588235295 0.5843137254901961 0.8705882352941177 1.0" contype="1" conaffinity="1" pos="-3.469446951953614e-17 0.0 0.12145091716924164" quat="1.0 0.0 0.0 0.0" size="0.009999999776482582 0.009999999776482582 0.054680756876868325" />
            <geom name="L7_vis2" type="box" rgba="0.5176470588235295 0.5843137254901961 0.8705882352941177 1.0" contype="1" conaffinity="1" pos="-2.7755575615628914e-17 0.0 0.09306583691129627" quat="1.0 0.0 0.0 0.0" size="0.009999999776482582 0.009999999776482582 0.08306583713481369" />
            <inertial pos="-0.0 0.0 0.08097" mass="0.04839422216852606" diaginertia="0.012721123994364246 0.012745589044769032 2.7691331737280837e-05" />
            <body name="EE" pos="-5.551115123125783e-17 0.0 0.18613167382259255" quat="0.10535080902060162 5.444071275446129e-17 0.9944351195722648 5.444071275446129e-17">
              <geom name="EE_vis0" type="sphere" rgba="0.6431372549019608 0.6666666666666666 0.9058823529411765 1.0" contype="1" conaffinity="1" pos="0.0 0.0 0.0" quat="1.0 0.0 0.0 0.0" size="0.002142857142857143" />
              <inertial pos="0.0 0.0 0.0" mass="2.6790549596939203e-05" diaginertia="4.920713191274548e-11 4.920713191274548e-11 4.920713191274548e-11" />
            </body>
            <body name="Main_ee_L7Unit" pos="-5.551115123125783e-17 0.0 0.18613167382259255" quat="0.07449427146195642 0.07449427146195635 0.7031718164996036 -0.7031718164996037">
              <geom name="Main_ee_L7Unit_vis0" type="cylinder" rgba="0.5176470588235295 0.5843137254901961 0.8705882352941177 0.9" contype="1" conaffinity="1" size="0.016 0.015" />
              <inertial pos="0 0 0" mass="0.1" diaginertia="0.00065 0.00065 0.0008" />
            </body>
            <body name="Main_connection_2_L7Pseudo" pos="0.0 0.0 0.05677016051589075" quat="0.930230301061354 0.0 -0.366976275782649 0.0">
              <geom name="Main_connection_2_L7Pseudo_vis0" type="sphere" rgba="0.5176470588235295 0.5843137254901961 0.8705882352941177 0.5" contype="1" conaffinity="1" size="0.01428571396640369" />
              <inertial pos="0 0 0" mass="0.05" diaginertia="4.08163247059803e-06 4.08163247059803e-06 4.08163247059803e-06" />
            </body>
          </body>
          <body name="Main_knee_L6Unit" pos="1.6016447257671449e-16 0.0 0.3402425605358625" quat="0.6977357255379986 0.6977357255379985 0.11473821206539198 -0.11473821206539196">
            <geom name="Main_knee_L6Unit_vis0" type="cylinder" rgba="0.1568627450980392 0.42745098039215684 0.8 0.9" contype="1" conaffinity="1" size="0.016 0.015" />
            <inertial pos="0 0 0" mass="0.1" diaginertia="0.00065 0.00065 0.0008" />
          </body>
          <body name="Main_connection_1_L6Pseudo" pos="-0.04865468615662824 0.0 0.2143528131375934" quat="0.746533357588638 0.0 -0.6653479886551358 0.0">
            <geom name="Main_connection_1_L6Pseudo_vis0" type="sphere" rgba="0.1568627450980392 0.42745098039215684 0.8 0.5" contype="1" conaffinity="1" size="0.01428571396640369" />
            <inertial pos="0 0 0" mass="0.05" diaginertia="4.08163247059803e-06 4.08163247059803e-06 4.08163247059803e-06" />
          </body>
        </body>
        <body name="Main_ground_GActuator" pos="0.0 0.029999999776482583 0.0" quat="0.040592684466751336 0.04059268446675125 0.7059406731218868 -0.7059406731218869">
          <geom name="Main_ground_GActuator_vis0" type="cylinder" rgba="0.37254901960784315 0.5019607843137255 0.8352941176470589 0.9" contype="1" conaffinity="1" size="0.048 0.02" />
          <inertial pos="0 0 0" mass="0.44" diaginertia="0.0067466666666666664 0.0067466666666666664 0.01056" />
        </body>
        <body name="Main_ground_GUnit" pos="0.0 0.0 0.0" quat="0.040592684466751336 0.04059268446675125 0.7059406731218868 -0.7059406731218869">
          <geom name="Main_ground_GUnit_vis0" type="cylinder" rgba="0.37254901960784315 0.5019607843137255 0.8352941176470589 0.9" contype="1" conaffinity="1" size="0.009999999776482582 0.009999999776482582" />
          <inertial pos="0 0 0" mass="0.1" diaginertia="0.00041666665735344094 0.00041666665735344094 0.0004999999888241291" />
        </body>
        <body name="L3" pos="-0.195 0.0 0.04680000000000001" quat="-0.12993279108591807 6.866935021292796e-17 0.9915228034698058 6.866935021292796e-17">
          <joint name="Ground_connection" type="hinge" axis="0 1 0" range="-3.141592653589793 3.141592653589793" damping="0.1" />
          <geom name="L3_vis0" type="box" rgba="0.01568627450980392 0.5058823529411764 0.29411764705882354 1.0" contype="1" conaffinity="1" pos="0.0 0.0 0.10091" quat="1.0 0.0 0.0 0.0" size="0.01 0.01 0.09090713552569016" />
          <inertial pos="0.0 0.0 0.10091" mass="0.04727171047335888" diaginertia="0.0001317952193855673 0.0001317952193855673 3.151447364890592e-06" />
          <body name="L4" pos="2.7755575615628914e-17 0.0 0.20181427105138033" quat="0.7961296417790595 0.0 -0.6051260971737595 0.0">
            <joint name="branch_0" type="hinge" axis="0 1 0" range="-3.141592653589793 3.141592653589793" damping="0.1" />
            <geom name="L4_vis0" type="box" rgba="0.0 0.6627450980392157 0.3607843137254902 1.0" contype="1" conaffinity="1" pos="-0.022628432928209194 0.0 0.21059178040871757" quat="0.44808742985417144 -2.7303641841988502e-17 -0.8939897399896057 2.7303641841988502e-17" size="0.009999999776482582 0.009999999776482582 0.018244194361428292" />
            <geom name="L4_vis1" type="box" rgba="0.0 0.6627450980392157 0.3607843137254902 1.0" contype="1" conaffinity="1" pos="0.0 0.0 0.1137470517475068" quat="1.0 0.0 0.0 0.0" size="0.009999999776482582 0.009999999776482582 0.10374705197102424" />
            <geom name="L4_vis2" type="box" rgba="0.0 0.6627450980392157 0.3607843137254902 1.0" contype="1" conaffinity="1" pos="-0.022628432928209194 0.0 0.09684472866121073" quat="0.11451756425717269 5.3817327657966684e-17 0.9934212235887677 5.3817327657966684e-17" size="0.009999999776482582 0.009999999776482582 0.08945324273601672" />
            <inertial pos="-0.01509 0.0 0.14039" mass="0.11082958592606866" diaginertia="0.012959578924386614 0.014870272115856353 0.001918081830201178" />
            <body name="L5" pos="-0.04525686585641839 0.0 0.1936894573224215" quat="0.9648892015411091 0.0 -0.26265724575834726 0.0">
              <joint name="branch_1" type="hinge" axis="0 1 0" range="-3.141592653589793 3.141592653589793" damping="0.1" />
              <geom name="L5_vis0" type="box" rgba="0.0 0.8274509803921568 0.4196078431372549 1.0" contype="1" conaffinity="1" pos="0.0 0.0 0.065" quat="1.0 0.0 0.0 0.0" size="0.01 0.01 0.055" />
              <inertial pos="0.0 0.0 0.065" mass="0.028600000000000004" diaginertia="2.9791666666666668e-05 2.9791666666666668e-05 1.9066666666666671e-06" />
              <body name="Main_connection_1_L5Pseudo" pos="2.7755575615628914e-17 0.0 0.13" quat="1.0 0.0 0.0 0.0">
                <joint name="Main_connection_1_L5_revolute" type="hinge" axis="0 1 0" range="-3.141592653589793 3.141592653589793" damping="0.1" />
                <geom name="Main_connection_1_L5Pseudo_vis0" type="sphere" rgba="0.0 0.8274509803921568 0.4196078431372549 0.5" contype="1" conaffinity="1" size="0.014285714285714287" />
                <inertial pos="0 0 0" mass="0.05" diaginertia="4.081632653061226e-06 4.081632653061226e-06 4.081632653061226e-06" />
              </body>
            </body>
            <body name="branch_1_L4Unit" pos="-0.04525686585641839 0.0 0.1936894573224215" quat="0.6822796975033918 0.6822796975033916 -0.18572671960350884 0.18572671960350878">
              <geom name="branch_1_L4Unit_vis0" type="cylinder" rgba="0.0 0.6627450980392157 0.3607843137254902 0.9" contype="1" conaffinity="1" size="0.016 0.015" />
              <inertial pos="0 0 0" mass="0.1" diaginertia="0.00065 0.00065 0.0008" />
            </body>
            <body name="L8" pos="0.0 0.0 0.22749410349501362" quat="0.9690574069405038 0.0 0.24683545542273044 0.0">
              <joint name="branch_2" type="hinge" axis="0 1 0" range="-3.141592653589793 3.141592653589793" damping="0.1" />
              <geom name="L8_vis0" type="box" rgba="0.0 1.0 0.4666666666666667 1.0" contype="1" conaffinity="1" pos="0.0 0.0 0.0758" quat="1.0 0.0 0.0 0.0" size="0.01 0.01 0.06580237463298892" />
              <inertial pos="0.0 0.0 0.0758" mass="0.03421723480915424" diaginertia="5.0526908379020675e-05 5.0526908379020675e-05 2.2811489872769493e-06" />
              <body name="Main_connection_2_L8Pseudo" pos="0.0 0.0 0.1516047492659778" quat="1.0 0.0 0.0 0.0">
                <joint name="Main_connection_2_L8_revolute" type="hinge" axis="0 1 0" range="-3.141592653589793 3.141592653589793" damping="0.1" />
                <geom name="Main_connection_2_L8Pseudo_vis0" type="sphere" rgba="0.0 1.0 0.4666666666666667 0.5" contype="1" conaffinity="1" size="0.014285714285714287" />
                <inertial pos="0 0 0" mass="0.05" diaginertia="4.081632653061226e-06 4.081632653061226e-06 4.081632653061226e-06" />
              </body>
            </body>
            <body name="branch_2_L4Unit" pos="0.0 0.0 0.22749410349501362" quat="0.6852270638066821 0.6852270638066817 0.17453902436668242 -0.1745390243666825">
              <geom name="branch_2_L4Unit_vis0" type="cylinder" rgba="0.0 0.6627450980392157 0.3607843137254902 0.9" contype="1" conaffinity="1" size="0.016 0.015" />
              <inertial pos="0 0 0" mass="0.1" diaginertia="0.00065 0.00065 0.0008" />
            </body>
          </body>
          <body name="branch_0_L3Unit" pos="2.7755575615628914e-17 0.0 0.20181427105138033" quat="0.56294866840559 0.5629486684055898 -0.4278887667845151 0.42788876678451504">
            <geom name="branch_0_L3Unit_vis0" type="cylinder" rgba="0.01568627450980392 0.5058823529411764 0.29411764705882354 0.9" contype="1" conaffinity="1" size="0.016 0.015" />
            <inertial pos="0 0 0" mass="0.1" diaginertia="0.00065 0.00065 0.0008" />
          </body>
        </body>
        <body name="Ground_connection_GActuator" pos="-0.195 0.03 0.04680000000000001" quat="0.09187635767534795 0.09187635767534752 -0.7011124980345963 0.701112498034596">
          <geom name="Ground_connection_GActuator_vis0" type="cylinder" rgba="0.37254901960784315 0.5019607843137255 0.8352941176470589 0.9" contype="1" conaffinity="1" size="0.048 0.02" />
          <inertial pos="0 0 0" mass="0.44" diaginertia="0.0067466666666666664 0.0067466666666666664 0.01056" />
        </body>
        <body name="Ground_connection_GUnit" pos="-0.195 0.0 0.04680000000000001" quat="0.09187635767534795 0.09187635767534752 -0.7011124980345963 0.701112498034596">
          <geom name="Ground_connection_GUnit_vis0" type="cylinder" rgba="0.37254901960784315 0.5019607843137255 0.8352941176470589 0.9" contype="1" conaffinity="1" size="0.01 0.01" />
          <inertial pos="0 0 0" mass="0.1" diaginertia="0.00041666666666666664 0.00041666666666666664 0.0005" />
        </body>
      </body>
    </body>
  </worldbody>
  <actuator>
    <motor name="Main_ground_motor" joint="Main_ground" gear="80" ctrlrange="-1.0 1.0" forcerange="-50 50" />
    <motor name="Main_knee_motor" joint="Main_knee" gear="150" ctrlrange="-1.0 1.0" forcerange="-50 50" />
    <motor name="Ground_connection_motor" joint="Ground_connection" gear="80" ctrlrange="-1.0 1.0" forcerange="-50 50" />
    <motor name="branch_0_motor" joint="branch_0" gear="1" ctrlrange="-1.0 1.0" forcerange="-50 50" />
    <motor name="branch_1_motor" joint="branch_1" gear="1" ctrlrange="-1.0 1.0" forcerange="-50 50" />
    <motor name="Main_connection_1_L5_revolute_motor" joint="Main_connection_1_L5_revolute" gear="1" ctrlrange="-1.0 1.0" forcerange="-50 50" />
    <motor name="branch_2_motor" joint="branch_2" gear="1" ctrlrange="-1.0 1.0" forcerange="-50 50" />
    <motor name="Main_connection_2_L8_revolute_motor" joint="Main_connection_2_L8_revolute" gear="1" ctrlrange="-1.0 1.0" forcerange="-50 50" />
  </actuator>
</mujoco>