<?xml version="1.0" encoding="utf-8"?>
<mujoco model="robot_1">
  <compiler angle="radian" inertiafromgeom="true" coordinate="local" />
  <option timestep="0.01" gravity="0 0 -9.81" integrator="RK4" />
  <size njmax="500" nconmax="100" />
  <worldbody>
    <geom name="floor" type="plane" size="10 10 0.1" pos="0 0 0" rgba="0.8 0.9 0.9 1" />
    <light name="light1" pos="0 0 3" dir="0 0 -1" directional="true" />
    <body name="robot_root" pos="0 0 0.5" quat="1 0 0 0">
      <body name="G">
        <geom name="G_vis0" type="box" rgba="0.1568627450980392 0.42745098039215684 0.8 1.0" contype="1" conaffinity="1" pos="0.0 0.0 0.0" quat="1.0 0.0 0.0 0.0" size="0.04 0.04 0.04" />
        <inertial pos="0.0 0.0 0.0" mass="0.08347399110019947" diaginertia="8.903892384021277e-05 8.903892384021277e-05 8.903892384021277e-05" />
        <body name="L3" pos="0.0 0.0 0.0" quat="0.06047668423188785 5.741713201658111e-17 0.998169610168691 5.741713201658111e-17">
          <joint name="Main_ground" type="hinge" axis="0 1 0" range="-3.141592653589793 3.141592653589793" damping="0.1" />
          <geom name="L3_vis0" type="box" rgba="0.37254901960784315 0.5019607843137255 0.8352941176470589 1.0" contype="1" conaffinity="1" pos="-0.0335453797116682 0.0 0.30749931402362507" quat="0.971927930023144 0.0 0.23527876835984662 0.0" size="0.019999999552965164 0.019999999552965164 0.053347601805225145" />
          <geom name="L3_vis1" type="box" rgba="0.37254901960784315 0.5019607843137255 0.8352941176470589 1.0" contype="1" conaffinity="1" pos="-0.03354537971166819 0.0 0.12113609340324624" quat="0.13466621351140315 5.242864835118275e-17 0.9908910186990804 5.242864835118275e-17" size="0.019999999552965164 0.019999999552965164 0.10569505056835027" />
          <geom name="L3_vis2" type="box" rgba="0.37254901960784315 0.5019607843137255 0.8352941176470589 1.0" contype="1" conaffinity="1" pos="-8.0396400129425e-18 0.0 0.18636322062037886" quat="1.0 0.0 0.0 0.0" size="0.019999999552965164 0.019999999552965164 0.1663632210674137" />
          <inertial pos="-0.02236 0.0 0.205" mass="0.7542480601566578" diaginertia="0.12500084161050556 0.12869753843871176 0.003897829635256627" />
          <body name="L4" pos="-1.6079280025885e-17 0.0 0.3727264412407577" quat="0.9876821263722173 0.0 0.15647369505720535 0.0">
            <joint name="Main_knee" type="hinge" axis="0 1 0" range="-3.141592653589793 3.141592653589793" damping="0.1" />
            <geom name="L4_vis0" type="box" rgba="0.5176470588235295 0.5843137254901961 0.8705882352941177 1.0" contype="1" conaffinity="1" pos="2.0816681711721685e-17 0.0 0.11718041645257968" quat="1.0 0.0 0.0 0.0" size="0.019999999552965164 0.019999999552965164 0.09718041689961451" />
            <geom name="L4_vis1" type="box" rgba="0.5176470588235295 0.5843137254901961 0.8705882352941177 1.0" contype="1" conaffinity="1" pos="3.469446951953614e-17 0.0 0.16639619136266312" quat="1.0 0.0 0.0 0.0" size="0.019999999552965164 0.019999999552965164 0.04796464198953107" />
            <geom name="L4_vis2" type="box" rgba="0.5176470588235295 0.5843137254901961 0.8705882352941177 1.0" contype="1" conaffinity="1" pos="1.3877787807814457e-17 0.0 0.04921577491008344" quat="1.0 0.0 0.0 0.0" size="0.019999999552965164 0.019999999552965164 0.02921577535711828" />
            <inertial pos="0.0 0.0 0.11093" mass="0.27110860821538063" diaginertia="0.09751211219620336 0.09769377780925784 0.00025396123848237884" />
            <body name="EE" pos="4.163336342344337e-17 0.0 0.23436083290515936" quat="0.09645554711881314 5.504063266352305e-17 0.9953372932981113 5.504063266352305e-17">
              <geom name="EE_vis0" type="sphere" rgba="0.6431372549019608 0.6666666666666666 0.9058823529411765 1.0" contype="1" conaffinity="1" pos="0.0 0.0 0.0" quat="1.0 0.0 0.0 0.0" size="0.002142857142857143" />
              <inertial pos="0.0 0.0 0.0" mass="2.979933439782622e-05" diaginertia="5.473347134294612e-11 5.473347134294612e-11 5.473347134294612e-11" />
            </body>
            <body name="Main_ee_L4Unit" pos="4.163336342344337e-17 0.0 0.23436083290515936" quat="0.06820437145077145 0.06820437145077136 0.7038097496589579 -0.703809749658958">
              <geom name="Main_ee_L4Unit_vis0" type="cylinder" rgba="0.5176470588235295 0.5843137254901961 0.8705882352941177 0.9" contype="1" conaffinity="1" size="0.016 0.015" />
              <inertial pos="0 0 0" mass="0.1" diaginertia="0.00065 0.00065 0.0008" />
            </body>
            <body name="Main_connection_2_L4Pseudo" pos="2.7755575615628914e-17 0.0 0.09843154982016689" quat="0.09645554711881314 5.504063266352305e-17 0.9953372932981113 5.504063266352305e-17">
              <joint name="Main_connection_2_L4_revolute" type="hinge" axis="0 1 0" range="-3.141592653589793 3.141592653589793" damping="0.1" />
              <geom name="Main_connection_2_L4Pseudo_vis0" type="sphere" rgba="0.5176470588235295 0.5843137254901961 0.8705882352941177 0.5" contype="1" conaffinity="1" size="0.02857142793280738" />
              <inertial pos="0 0 0" mass="0.05" diaginertia="1.632652988239212e-05 1.632652988239212e-05 1.632652988239212e-05" />
            </body>
          </body>
          <body name="Main_knee_L3Unit" pos="-1.6079280025885e-17 0.0 0.3727264412407577" quat="0.6983967292145435 0.6983967292145434 0.11064361085226583 -0.1106436108522659">
            <geom name="Main_knee_L3Unit_vis0" type="cylinder" rgba="0.37254901960784315 0.5019607843137255 0.8352941176470589 0.9" contype="1" conaffinity="1" size="0.016 0.015" />
            <inertial pos="0 0 0" mass="0.1" diaginertia="0.00065 0.00065 0.0008" />
          </body>
          <body name="L6" pos="-0.06709075942333638 0.0 0.24227218680649248" quat="0.7485759736486595 0.0 -0.6630490266005686 0.0">
            <joint name="Main_connection_1" type="hinge" axis="0 1 0" range="-3.141592653589793 3.141592653589793" damping="0.1" />
            <geom name="L6_vis0" type="box" rgba="0.01568627450980392 0.5058823529411764 0.29411764705882354 1.0" contype="1" conaffinity="1" pos="0.0 0.0 0.0375" quat="1.0 0.0 0.0 0.0" size="0.02 0.02 0.017499999999999984" />
            <inertial pos="0.0 0.0 0.0375" mass="0.04048799999999997" diaginertia="9.531549999999985e-06 9.531549999999985e-06 1.0796799999999991e-05" />
            <body name="L5" pos="0.0 0.0 0.07499999999999997" quat="0.4869558309959911 2.3664509268372513e-17 0.8734265960336929 2.3664509268372513e-17">
              <joint name="branch_1" type="hinge" axis="0 1 0" range="-3.141592653589793 3.141592653589793" damping="0.1" />
              <geom name="L5_vis0" type="box" rgba="0.0 0.6627450980392157 0.3607843137254902 1.0" contype="1" conaffinity="1" pos="-0.0 0.0 0.13766" quat="1.0 0.0 0.0 0.0" size="0.02 0.02 0.11766099892489519" />
              <inertial pos="-0.0 0.0 0.13766" mass="0.2722204871126375" diaginertia="0.001292512914843472 0.001292512914843472 7.259212989670334e-05" />
              <body name="Main_connection_2_L5Pseudo" pos="-2.0816681711721685e-17 0.0 0.2753219978497904" quat="0.273276098688512 4.216823509701657e-17 0.9619356391597031 4.216823509701657e-17">
                <geom name="Main_connection_2_L5Pseudo_vis0" type="sphere" rgba="0.0 0.6627450980392157 0.3607843137254902 0.5" contype="1" conaffinity="1" size="0.028571428571428574" />
                <inertial pos="0 0 0" mass="0.05" diaginertia="1.6326530612244903e-05 1.6326530612244903e-05 1.6326530612244903e-05" />
              </body>
            </body>
            <body name="branch_1_L6Unit" pos="0.0 0.0 0.07499999999999997" quat="0.34432977023559574 0.3443297702355957 0.6176058689241074 -0.6176058689241075">
              <geom name="branch_1_L6Unit_vis0" type="cylinder" rgba="0.01568627450980392 0.5058823529411764 0.29411764705882354 0.9" contype="1" conaffinity="1" size="0.016 0.015" />
              <inertial pos="0 0 0" mass="0.1" diaginertia="0.00065 0.00065 0.0008" />
            </body>
          </body>
          <body name="Main_connection_1_L3Actuator" pos="-0.06709075942333638 0.03999999955296517 0.24227218680649248" quat="0.5293231472002894 0.5293231472002893 -0.46884646296840177 0.4688464629684016">
            <geom name="Main_connection_1_L3Actuator_vis0" type="cylinder" rgba="0.37254901960784315 0.5019607843137255 0.8352941176470589 0.9" contype="1" conaffinity="1" size="0.048 0.02" />
            <inertial pos="0 0 0" mass="0.44" diaginertia="0.0067466666666666664 0.0067466666666666664 0.01056" />
          </body>
          <body name="Main_connection_1_L3Unit" pos="-0.06709075942333638 0.0 0.24227218680649248" quat="0.5293231472002894 0.5293231472002893 -0.46884646296840177 0.4688464629684016">
            <geom name="Main_connection_1_L3Unit_vis0" type="cylinder" rgba="0.37254901960784315 0.5019607843137255 0.8352941176470589 0.9" contype="1" conaffinity="1" size="0.019999999552965164 0.019999999552965164" />
            <inertial pos="0 0 0" mass="0.1" diaginertia="0.0008333333147068819 0.0008333333147068819 0.0009999999776482583" />
          </body>
        </body>
        <body name="Main_ground_GActuator" pos="0.0 0.03999999955296517 0.0" quat="-0.04276347352404526 -0.04276347352404564 -0.7058125001246142 0.7058125001246138">
          <geom name="Main_ground_GActuator_vis0" type="cylinder" rgba="0.1568627450980392 0.42745098039215684 0.8 0.9" contype="1" conaffinity="1" size="0.048 0.02" />
          <inertial pos="0 0 0" mass="0.44" diaginertia="0.0067466666666666664 0.0067466666666666664 0.01056" />
        </body>
        <body name="Main_ground_GUnit" pos="0.0 0.0 0.0" quat="-0.04276347352404526 -0.04276347352404564 -0.7058125001246142 0.7058125001246138">
          <geom name="Main_ground_GUnit_vis0" type="cylinder" rgba="0.1568627450980392 0.42745098039215684 0.8 0.9" contype="1" conaffinity="1" size="0.019999999552965164 0.019999999552965164" />
          <inertial pos="0 0 0" mass="0.1" diaginertia="0.0008333333147068819 0.0008333333147068819 0.0009999999776482583" />
        </body>
      </body>
    </body>
  </worldbody>
  <actuator>
    <motor name="Main_ground_motor" joint="Main_ground" gear="80" ctrlrange="-1.0 1.0" forcerange="-50 50" />
    <motor name="Main_knee_motor" joint="Main_knee" gear="150" ctrlrange="-1.0 1.0" forcerange="-50 50" />
    <motor name="Main_connection_2_L4_revolute_motor" joint="Main_connection_2_L4_revolute" gear="1" ctrlrange="-1.0 1.0" forcerange="-50 50" />
    <motor name="Main_connection_1_motor" joint="Main_connection_1" gear="1" ctrlrange="-1.0 1.0" forcerange="-50 50" />
    <motor name="branch_1_motor" joint="branch_1" gear="1" ctrlrange="-1.0 1.0" forcerange="-50 50" />
  </actuator>
</mujoco>