<?xml version="1.0"?>
<robot  name="Robot" >
 <link  name="G" >
  <visual >
   <origin  xyz="0.0 0.0 0.0"  rpy="0.0 0.0 0.0" />
   <geometry >
    <box  size="0.067 0.067 0.067" />
   </geometry>
   <material  name="G_Material" >
    <color  rgba="0.1568627450980392 0.42745098039215684 0.8 1.0" />
   </material>
  </visual>
  <collision  name="G_Collision" >
   <origin  xyz="0.0 0.0 0.0"  rpy="0.0 0.0 0.0" />
   <geometry >
    <box  size="0.067 0.067 0.067" />
   </geometry>
  </collision>
  <inertial >
   <origin  xyz="0.0 0.0 0.0"  rpy="0.0 0.0 0.0" />
   <mass  value="0.04903493747122909" />
   <inertia  izz="3.66863057180579e-05"  ixz="0.0"  ixy="0.0"  ixx="3.66863057180579e-05"  iyy="3.66863057180579e-05"  iyz="0.0" />
  </inertial>
 </link>
 <link  name="L6" >
  <visual >
   <origin  xyz="0.0 0.0 0.07649"  rpy="0.0 0.0 0.0" />
   <geometry >
    <box  size="0.0335 0.0335 0.11947058540778355" />
   </geometry>
   <material  name="L6_Material" >
    <color  rgba="0.37254901960784315 0.5019607843137255 0.8352941176470589 1.0" />
   </material>
  </visual>
  <collision  name="L6_Collision" >
   <origin  xyz="0.0 0.0 0.07649"  rpy="0.0 0.0 0.0" />
   <geometry >
    <box  size="0.0335 0.0335 0.11947058540778355" />
   </geometry>
  </collision>
  <inertial >
   <origin  xyz="0.0 0.0 0.07649"  rpy="0.0 0.0 0.0" />
   <mass  value="0.09693685001461892" />
   <inertia  izz="1.8131229988151018e-05"  ixz="0.0"  ixy="0.0"  ixx="0.0001243657034733558"  iyy="0.0001243657034733558"  iyz="0.0" />
  </inertial>
 </link>
 <link  name="L5" >
  <visual >
   <origin  xyz="3.122502256758253e-17 0.0 0.1258967831201417"  rpy="0.0 0.0 0.0" />
   <geometry >
    <box  size="0.03350000083446503 0.03350000083446503 0.21829356540581835" />
   </geometry>
   <material  name="L5_Material" >
    <color  rgba="0.5176470588235295 0.5843137254901961 0.8705882352941177 1.0" />
   </material>
  </visual>
  <collision  name="L5_0_Collision_1" >
   <origin  xyz="3.122502256758253e-17 0.0 0.1258967831201417"  rpy="0.0 0.0 0.0" />
   <geometry >
    <box  size="0.03350000083446503 0.03350000083446503 0.21829356540581835" />
   </geometry>
  </collision>
  <collision  name="L5_0_Collision_2" >
   <origin  xyz="3.122502256758253e-17 0.0 0.1258967831201417"  rpy="0.0 0.0 0.0" />
   <geometry >
    <box  size="0.03350000083446503 0.03350000083446503 0.21829356540581835" />
   </geometry>
  </collision>
  <visual >
   <origin  xyz="1.3877787807814457e-17 0.0 0.04406387409204959"  rpy="0.0 0.0 0.0" />
   <geometry >
    <box  size="0.03350000083446503 0.03350000083446503 0.05462774734963416" />
   </geometry>
   <material  name="L5_Material" >
    <color  rgba="0.5176470588235295 0.5843137254901961 0.8705882352941177 1.0" />
   </material>
  </visual>
  <collision  name="L5_1_Collision_1" >
   <origin  xyz="1.3877787807814457e-17 0.0 0.04406387409204959"  rpy="0.0 0.0 0.0" />
   <geometry >
    <box  size="0.03350000083446503 0.03350000083446503 0.05462774734963416" />
   </geometry>
  </collision>
  <collision  name="L5_1_Collision_2" >
   <origin  xyz="1.3877787807814457e-17 0.0 0.04406387409204959"  rpy="0.0 0.0 0.0" />
   <geometry >
    <box  size="0.03350000083446503 0.03350000083446503 0.05462774734963416" />
   </geometry>
  </collision>
  <visual >
   <origin  xyz="3.8163916471489756e-17 0.0 0.16996065721219128"  rpy="0.0 0.0 0.0" />
   <geometry >
    <box  size="0.03350000083446503 0.03350000083446503 0.13016581722171916" />
   </geometry>
   <material  name="L5_Material" >
    <color  rgba="0.5176470588235295 0.5843137254901961 0.8705882352941177 1.0" />
   </material>
  </visual>
  <collision  name="L5_2_Collision_1" >
   <origin  xyz="3.8163916471489756e-17 0.0 0.16996065721219128"  rpy="0.0 0.0 0.0" />
   <geometry >
    <box  size="0.03350000083446503 0.03350000083446503 0.13016581722171916" />
   </geometry>
  </collision>
  <collision  name="L5_2_Collision_2" >
   <origin  xyz="3.8163916471489756e-17 0.0 0.16996065721219128"  rpy="0.0 0.0 0.0" />
   <geometry >
    <box  size="0.03350000083446503 0.03350000083446503 0.13016581722171916" />
   </geometry>
  </collision>
  <inertial >
   <origin  xyz="0.0 0.0 0.11331"  rpy="0.0 0.0 0.0" />
   <mass  value="0.20430196607254722" />
   <inertia  izz="9.923234039844751e-05"  ixz="0.0010645589339550272"  ixy="-8.254583497125634e-14"  ixx="0.0318890529501516"  iyy="0.03195007230862345"  iyz="-3.621784271123597e-12" />
  </inertial>
 </link>
 <link  name="EE" >
  <visual >
   <origin  xyz="0.0 0.0 0.0"  rpy="0.0 0.0 0.0" />
   <geometry >
    <sphere  radius="0.002142857142857143" />
   </geometry>
   <material  name="EE_Material" >
    <color  rgba="0.6431372549019608 0.6666666666666666 0.9058823529411765 1.0" />
   </material>
  </visual>
  <collision  name="EE_Collision" >
   <origin  xyz="0.0 0.0 0.0"  rpy="0.0 0.0 0.0" />
   <geometry >
    <sphere  radius="0.002142857142857143" />
   </geometry>
  </collision>
  <inertial >
   <origin  xyz="0.0 0.0 0.0"  rpy="0.0 0.0 0.0" />
   <mass  value="2.979933439782622e-05" />
   <inertia  izz="5.473347134294612e-11"  ixz="0.0"  ixy="0.0"  ixx="5.473347134294612e-11"  iyy="5.473347134294612e-11"  iyz="0.0" />
  </inertial>
 </link>
 <link  name="L3" >
  <visual >
   <origin  xyz="0.0 0.0 0.10078"  rpy="0.0 0.0 0.0" />
   <geometry >
    <box  size="0.0335 0.0335 0.16805644370746375" />
   </geometry>
   <material  name="L3_Material" >
    <color  rgba="0.01568627450980392 0.5058823529411764 0.29411764705882354 1.0" />
   </material>
  </visual>
  <collision  name="L3_Collision" >
   <origin  xyz="0.0 0.0 0.10078"  rpy="0.0 0.0 0.0" />
   <geometry >
    <box  size="0.0335 0.0335 0.16805644370746375" />
   </geometry>
  </collision>
  <inertial >
   <origin  xyz="0.0 0.0 0.10078"  rpy="0.0 0.0 0.0" />
   <mass  value="0.136358771676357" />
   <inertia  izz="2.5504771918965276e-05"  ixz="0.0"  ixy="0.0"  ixx="0.0003336837577936235"  iyy="0.0003336837577936235"  iyz="0.0" />
  </inertial>
 </link>
 <link  name="L4" >
  <visual >
   <origin  xyz="-0.0 0.0 0.07355"  rpy="0.0 0.0 0.0" />
   <geometry >
    <box  size="0.0335 0.0335 0.11359350767454013" />
   </geometry>
   <material  name="L4_Material" >
    <color  rgba="0.0 0.6627450980392157 0.3607843137254902 1.0" />
   </material>
  </visual>
  <collision  name="L4_Collision" >
   <origin  xyz="-0.0 0.0 0.07355"  rpy="0.0 0.0 0.0" />
   <geometry >
    <box  size="0.0335 0.0335 0.11359350767454013" />
   </geometry>
  </collision>
  <inertial >
   <origin  xyz="-0.0 0.0 0.07355"  rpy="0.0 0.0 0.0" />
   <mass  value="0.09216826701314518" />
   <inertia  izz="1.723930627591703e-05"  ixz="0.0"  ixy="0.0"  ixx="0.0001077273072689468"  iyy="0.0001077273072689468"  iyz="0.0" />
  </inertial>
 </link>
 <joint  type="revolute"  name="Main_ground" >
  <parent  link="G" />
  <child  link="L6" />
  <origin  xyz="0.0 0.0 0.0"  rpy="3.141592653589793 0.1973955598498811 3.141592653589793" />
  <axis  xyz="0 1 0" />
  <limit  lower="-3.141592653589793"  effort="10.2"  upper="3.141592653589793"  velocity="23.99988291783386" />
  <dynamics  friction="0"  damping="0.05" />
 </joint>
 <joint  type="fixed"  name="Main_ground_G_WeldActuator" >
  <parent  link="G" />
  <child  link="Main_ground_GActuator" />
  <origin  xyz="0.0 0.036750000000000005 0.0"  rpy="-1.5707963267948966 0.1973955598498811 -3.141592653589793" />
 </joint>
 <link  name="Main_ground_GActuator" >
  <visual >
   <geometry >
    <cylinder  length="0.04"  radius="0.048" />
   </geometry>
   <material  name="Main_ground_GActuator_Material" >
    <color  rgba="0.1568627450980392 0.42745098039215684 0.8 0.9" />
   </material>
  </visual>
  <inertial >
   <inertia  izz="0.01056"  ixz="0.0"  ixy="0.0"  ixx="0.0067466666666666664"  iyy="0.0067466666666666664"  iyz="0.0" />
   <mass  value="0.44" />
  </inertial>
 </link>
 <link  name="Main_ground_GUnit" >
  <visual >
   <geometry >
    <cylinder  length="0.0335"  radius="0.01675" />
   </geometry>
   <material  name="Main_ground_GUnit_Material" >
    <color  rgba="0.1568627450980392 0.42745098039215684 0.8 0.9" />
   </material>
  </visual>
  <inertial >
   <inertia  izz="0.0008375000000000001"  ixz="0.0"  ixy="0.0"  ixx="0.0006979166666666668"  iyy="0.0006979166666666668"  iyz="0.0" />
   <mass  value="0.1" />
  </inertial>
 </link>
 <joint  type="fixed"  name="Main_ground_G_WeldUnit" >
  <parent  link="G" />
  <child  link="Main_ground_GUnit" />
  <origin  xyz="0.0 0.0 0.0"  rpy="-1.5707963267948966 0.1973955598498811 -3.141592653589793" />
 </joint>
 <joint  type="revolute"  name="Main_knee" >
  <parent  link="L6" />
  <child  link="L5" />
  <origin  xyz="3.9850810789398094e-17 0.0 0.15297058540778355"  rpy="0.0 0.3168244858682192 0.0" />
  <axis  xyz="0 1 0" />
  <limit  lower="-3.141592653589793"  effort="600.0"  upper="3.141592653589793"  velocity="6.283185307179586" />
  <dynamics  friction="0"  damping="0.05" />
 </joint>
 <link  name="Main_knee_L6Unit" >
  <visual >
   <geometry >
    <cylinder  length="0.03"  radius="0.016" />
   </geometry>
   <material  name="Main_knee_L6Unit_Material" >
    <color  rgba="0.37254901960784315 0.5019607843137255 0.8352941176470589 0.9" />
   </material>
  </visual>
  <inertial >
   <inertia  izz="0.0008"  ixz="0.0"  ixy="0.0"  ixx="0.00065"  iyy="0.00065"  iyz="0.0" />
   <mass  value="0.1" />
  </inertial>
 </link>
 <joint  type="fixed"  name="Main_knee_L6_WeldUnit" >
  <parent  link="L6" />
  <child  link="Main_knee_L6Unit" />
  <origin  xyz="3.9850810789398094e-17 0.0 0.15297058540778355"  rpy="1.5707963267948963 0.3168244858682192 0.0" />
 </joint>
 <joint  type="fixed"  name="Main_ee" >
  <parent  link="L5" />
  <child  link="EE" />
  <origin  xyz="5.551115123125783e-17 0.0 0.2517935662402834"  rpy="3.141592653589793 0.11942892601833832 3.141592653589793" />
 </joint>
 <link  name="Main_ee_L5Unit" >
  <visual >
   <geometry >
    <cylinder  length="0.03"  radius="0.016" />
   </geometry>
   <material  name="Main_ee_L5Unit_Material" >
    <color  rgba="0.5176470588235295 0.5843137254901961 0.8705882352941177 0.9" />
   </material>
  </visual>
  <inertial >
   <inertia  izz="0.0008"  ixz="0.0"  ixy="0.0"  ixx="0.00065"  iyy="0.00065"  iyz="0.0" />
   <mass  value="0.1" />
  </inertial>
 </link>
 <joint  type="fixed"  name="Main_ee_L5_WeldUnit" >
  <parent  link="L5" />
  <child  link="Main_ee_L5Unit" />
  <origin  xyz="5.551115123125783e-17 0.0 0.2517935662402834"  rpy="-1.5707963267948972 0.11942892601833832 -3.141592653589793" />
 </joint>
 <joint  type="revolute"  name="Ground_connection" >
  <parent  link="G" />
  <child  link="L3" />
  <origin  xyz="-0.15 0.0 -0.01"  rpy="3.141592653589793 0.12435499454676191 3.141592653589793" />
  <axis  xyz="0 1 0" />
  <limit  lower="-3.141592653589793"  effort="10.2"  upper="3.141592653589793"  velocity="23.99988291783386" />
  <dynamics  friction="0"  damping="0.05" />
 </joint>
 <joint  type="fixed"  name="Ground_connection_G_WeldActuator" >
  <parent  link="G" />
  <child  link="Ground_connection_GActuator" />
  <origin  xyz="-0.15 0.036750000000000005 -0.01"  rpy="-1.5707963267948966 0.12435499454676191 -3.141592653589793" />
 </joint>
 <link  name="Ground_connection_GActuator" >
  <visual >
   <geometry >
    <cylinder  length="0.04"  radius="0.048" />
   </geometry>
   <material  name="Ground_connection_GActuator_Material" >
    <color  rgba="0.1568627450980392 0.42745098039215684 0.8 0.9" />
   </material>
  </visual>
  <inertial >
   <inertia  izz="0.01056"  ixz="0.0"  ixy="0.0"  ixx="0.0067466666666666664"  iyy="0.0067466666666666664"  iyz="0.0" />
   <mass  value="0.44" />
  </inertial>
 </link>
 <link  name="Ground_connection_GUnit" >
  <visual >
   <geometry >
    <cylinder  length="0.0335"  radius="0.01675" />
   </geometry>
   <material  name="Ground_connection_GUnit_Material" >
    <color  rgba="0.1568627450980392 0.42745098039215684 0.8 0.9" />
   </material>
  </visual>
  <inertial >
   <inertia  izz="0.0008375000000000001"  ixz="0.0"  ixy="0.0"  ixx="0.0006979166666666668"  iyy="0.0006979166666666668"  iyz="0.0" />
   <mass  value="0.1" />
  </inertial>
 </link>
 <joint  type="fixed"  name="Ground_connection_G_WeldUnit" >
  <parent  link="G" />
  <child  link="Ground_connection_GUnit" />
  <origin  xyz="-0.15 0.0 -0.01"  rpy="-1.5707963267948966 0.12435499454676191 -3.141592653589793" />
 </joint>
 <joint  type="revolute"  name="branch_1" >
  <parent  link="L3" />
  <child  link="L4" />
  <origin  xyz="8.326672684688674e-17 0.0 0.20155644370746378"  rpy="0.0 -1.2583788347334055 0.0" />
  <axis  xyz="0 1 0" />
  <limit  lower="-3.141592653589793"  effort="600.0"  upper="3.141592653589793"  velocity="6.283185307179586" />
  <dynamics  friction="0"  damping="0.05" />
 </joint>
 <link  name="branch_1_L3Unit" >
  <visual >
   <geometry >
    <cylinder  length="0.03"  radius="0.016" />
   </geometry>
   <material  name="branch_1_L3Unit_Material" >
    <color  rgba="0.01568627450980392 0.5058823529411764 0.29411764705882354 0.9" />
   </material>
  </visual>
  <inertial >
   <inertia  izz="0.0008"  ixz="0.0"  ixy="0.0"  ixx="0.00065"  iyy="0.00065"  iyz="0.0" />
   <mass  value="0.1" />
  </inertial>
 </link>
 <joint  type="fixed"  name="branch_1_L3_WeldUnit" >
  <parent  link="L3" />
  <child  link="branch_1_L3Unit" />
  <origin  xyz="8.326672684688674e-17 0.0 0.20155644370746378"  rpy="1.5707963267948961 -1.2583788347334057 3.3306690738754696e-16" />
 </joint>
 <link  name="Main_connection_2_L4Pseudo" >
  <visual >
   <geometry >
    <sphere  radius="0.02392857142857143" />
   </geometry>
   <material  name="Main_connection_2_L4Pseudo_Material" >
    <color  rgba="0.0 0.6627450980392157 0.3607843137254902 0.5" />
   </material>
  </visual>
  <inertial >
   <mass  value="0.05" />
   <inertia  izz="1.1451530612244902e-05"  ixz="0.0"  ixy="0.0"  ixx="1.1451530612244902e-05"  iyy="1.1451530612244902e-05"  iyz="0.0" />
  </inertial>
 </link>
 <joint  type="revolute"  name="Main_connection_2_L4_revolute" >
  <parent  link="L4" />
  <child  link="Main_connection_2_L4Pseudo" />
  <origin  xyz="-2.7755575615628914e-17 0.0 0.14709350767454013"  rpy="0.0 0.0 0.0" />
  <axis  xyz="0 1 0" />
  <limit  lower="-3.141592653589793"  effort="600.0"  upper="3.141592653589793"  velocity="6.283185307179586" />
  <dynamics  friction="0"  damping="0.05" />
 </joint>
 <joint  type="fixed"  name="Main_connection_2_L4_Weld" >
  <parent  link="L5" />
  <child  link="Main_connection_2_L5Pseudo" />
  <origin  xyz="5.551115123125783e-17 0.0 0.08812774818409916"  rpy="0.0 -1.5021627552985055 0.0" />
 </joint>
 <link  name="Main_connection_2_L5Pseudo" >
  <visual >
   <geometry >
    <sphere  radius="0.02392857202461788" />
   </geometry>
   <material  name="Main_connection_2_L5Pseudo_Material" >
    <color  rgba="0.5176470588235295 0.5843137254901961 0.8705882352941177 0.5" />
   </material>
  </visual>
  <inertial >
   <mass  value="0.05" />
   <inertia  izz="1.145153118274651e-05"  ixz="0.0"  ixy="0.0"  ixx="1.145153118274651e-05"  iyy="1.145153118274651e-05"  iyz="0.0" />
  </inertial>
 </link>
</robot>