<?xml version="1.0"?>
<robot  name="Robot" >
 <link  name="G" >
  <visual >
   <origin  xyz="0.0 0.0 0.0"  rpy="0.0 0.0 0.0" />
   <geometry >
    <box  size="0.08 0.08 0.08" />
   </geometry>
   <material  name="G_Material" >
    <color  rgba="0.1568627450980392 0.42745098039215684 0.8 1.0" />
   </material>
  </visual>
  <collision  name="G_Collision" >
   <origin  xyz="0.0 0.0 0.0"  rpy="0.0 0.0 0.0" />
   <geometry >
    <box  size="0.08 0.08 0.08" />
   </geometry>
  </collision>
  <inertial >
   <origin  xyz="0.0 0.0 0.0"  rpy="0.0 0.0 0.0" />
   <mass  value="0.08347399110019947" />
   <inertia  izz="8.903892384021277e-05"  ixz="0.0"  ixy="0.0"  ixx="8.903892384021277e-05"  iyy="8.903892384021277e-05"  iyz="0.0" />
  </inertial>
 </link>
 <link  name="L3" >
  <visual >
   <origin  xyz="-0.0335453797116682 0.0 0.30749931402362507"  rpy="0.0 0.4750107562650965 0.0" />
   <geometry >
    <box  size="0.03999999910593033 0.03999999910593033 0.10669520361045029" />
   </geometry>
   <material  name="L3_Material" >
    <color  rgba="0.37254901960784315 0.5019607843137255 0.8352941176470589 1.0" />
   </material>
  </visual>
  <collision  name="L3_0_Collision" >
   <origin  xyz="-0.0335453797116682 0.0 0.30749931402362507"  rpy="0.0 0.4750107562650965 0.0" />
   <geometry >
    <box  size="0.03999999910593033 0.03999999910593033 0.10669520361045029" />
   </geometry>
  </collision>
  <collision  name="L3_0_Collision" >
   <origin  xyz="-0.0335453797116682 0.0 0.30749931402362507"  rpy="0.0 0.4750107562650965 0.0" />
   <geometry >
    <box  size="0.03999999910593033 0.03999999910593033 0.10669520361045029" />
   </geometry>
  </collision>
  <visual >
   <origin  xyz="-0.03354537971166819 0.0 0.12113609340324624"  rpy="3.141592653589793 0.2701531997114055 3.141592653589793" />
   <geometry >
    <box  size="0.03999999910593033 0.03999999910593033 0.21139010113670054" />
   </geometry>
   <material  name="L3_Material" >
    <color  rgba="0.37254901960784315 0.5019607843137255 0.8352941176470589 1.0" />
   </material>
  </visual>
  <collision  name="L3_1_Collision" >
   <origin  xyz="-0.03354537971166819 0.0 0.12113609340324624"  rpy="3.141592653589793 0.2701531997114055 3.141592653589793" />
   <geometry >
    <box  size="0.03999999910593033 0.03999999910593033 0.21139010113670054" />
   </geometry>
  </collision>
  <collision  name="L3_1_Collision" >
   <origin  xyz="-0.03354537971166819 0.0 0.12113609340324624"  rpy="3.141592653589793 0.2701531997114055 3.141592653589793" />
   <geometry >
    <box  size="0.03999999910593033 0.03999999910593033 0.21139010113670054" />
   </geometry>
  </collision>
  <visual >
   <origin  xyz="-8.0396400129425e-18 0.0 0.18636322062037886"  rpy="0.0 0.0 0.0" />
   <geometry >
    <box  size="0.03999999910593033 0.03999999910593033 0.3327264421348274" />
   </geometry>
   <material  name="L3_Material" >
    <color  rgba="0.37254901960784315 0.5019607843137255 0.8352941176470589 1.0" />
   </material>
  </visual>
  <collision  name="L3_2_Collision" >
   <origin  xyz="-8.0396400129425e-18 0.0 0.18636322062037886"  rpy="0.0 0.0 0.0" />
   <geometry >
    <box  size="0.03999999910593033 0.03999999910593033 0.3327264421348274" />
   </geometry>
  </collision>
  <collision  name="L3_2_Collision" >
   <origin  xyz="-8.0396400129425e-18 0.0 0.18636322062037886"  rpy="0.0 0.0 0.0" />
   <geometry >
    <box  size="0.03999999910593033 0.03999999910593033 0.3327264421348274" />
   </geometry>
  </collision>
  <inertial >
   <origin  xyz="-0.02236 0.0 0.205"  rpy="0.0 0.0 0.0" />
   <mass  value="0.7542480601566578" />
   <inertia  izz="0.003897829635256627"  ixz="0.020270828042675212"  ixy="-6.24448782341868e-21"  ixx="0.12500084161050556"  iyy="0.12869753843871176"  iyz="-2.015832535346828e-20" />
  </inertial>
 </link>
 <link  name="L4" >
  <visual >
   <origin  xyz="2.0816681711721685e-17 0.0 0.11718041645257968"  rpy="0.0 0.0 0.0" />
   <geometry >
    <box  size="0.03999999910593033 0.03999999910593033 0.19436083379922903" />
   </geometry>
   <material  name="L4_Material" >
    <color  rgba="0.5176470588235295 0.5843137254901961 0.8705882352941177 1.0" />
   </material>
  </visual>
  <collision  name="L4_0_Collision" >
   <origin  xyz="2.0816681711721685e-17 0.0 0.11718041645257968"  rpy="0.0 0.0 0.0" />
   <geometry >
    <box  size="0.03999999910593033 0.03999999910593033 0.19436083379922903" />
   </geometry>
  </collision>
  <collision  name="L4_0_Collision" >
   <origin  xyz="2.0816681711721685e-17 0.0 0.11718041645257968"  rpy="0.0 0.0 0.0" />
   <geometry >
    <box  size="0.03999999910593033 0.03999999910593033 0.19436083379922903" />
   </geometry>
  </collision>
  <visual >
   <origin  xyz="3.469446951953614e-17 0.0 0.16639619136266312"  rpy="0.0 0.0 0.0" />
   <geometry >
    <box  size="0.03999999910593033 0.03999999910593033 0.09592928397906214" />
   </geometry>
   <material  name="L4_Material" >
    <color  rgba="0.5176470588235295 0.5843137254901961 0.8705882352941177 1.0" />
   </material>
  </visual>
  <collision  name="L4_1_Collision" >
   <origin  xyz="3.469446951953614e-17 0.0 0.16639619136266312"  rpy="0.0 0.0 0.0" />
   <geometry >
    <box  size="0.03999999910593033 0.03999999910593033 0.09592928397906214" />
   </geometry>
  </collision>
  <collision  name="L4_1_Collision" >
   <origin  xyz="3.469446951953614e-17 0.0 0.16639619136266312"  rpy="0.0 0.0 0.0" />
   <geometry >
    <box  size="0.03999999910593033 0.03999999910593033 0.09592928397906214" />
   </geometry>
  </collision>
  <visual >
   <origin  xyz="1.3877787807814457e-17 0.0 0.04921577491008344"  rpy="0.0 0.0 0.0" />
   <geometry >
    <box  size="0.03999999910593033 0.03999999910593033 0.05843155071423656" />
   </geometry>
   <material  name="L4_Material" >
    <color  rgba="0.5176470588235295 0.5843137254901961 0.8705882352941177 1.0" />
   </material>
  </visual>
  <collision  name="L4_2_Collision" >
   <origin  xyz="1.3877787807814457e-17 0.0 0.04921577491008344"  rpy="0.0 0.0 0.0" />
   <geometry >
    <box  size="0.03999999910593033 0.03999999910593033 0.05843155071423656" />
   </geometry>
  </collision>
  <collision  name="L4_2_Collision" >
   <origin  xyz="1.3877787807814457e-17 0.0 0.04921577491008344"  rpy="0.0 0.0 0.0" />
   <geometry >
    <box  size="0.03999999910593033 0.03999999910593033 0.05843155071423656" />
   </geometry>
  </collision>
  <inertial >
   <origin  xyz="0.0 0.0 0.11093"  rpy="0.0 0.0 0.0" />
   <mass  value="0.27110860821538063" />
   <inertia  izz="0.00025396123848237884"  ixz="0.003408120061042342"  ixy="-5.926807160462514e-14"  ixx="0.09751211219620336"  iyy="0.09769377780925784"  iyz="-3.435265062261709e-12" />
  </inertial>
 </link>
 <link  name="EE" >
  <visual >
   <origin  xyz="0.0 0.0 0.0"  rpy="0.0 0.0 0.0" />
   <geometry >
    <sphere  radius="0.002142857142857143" />
   </geometry>
   <material  name="EE_Material" >
    <color  rgba="0.6431372549019608 0.6666666666666666 0.9058823529411765 1.0" />
   </material>
  </visual>
  <collision  name="EE_Collision" >
   <origin  xyz="0.0 0.0 0.0"  rpy="0.0 0.0 0.0" />
   <geometry >
    <sphere  radius="0.002142857142857143" />
   </geometry>
  </collision>
  <inertial >
   <origin  xyz="0.0 0.0 0.0"  rpy="0.0 0.0 0.0" />
   <mass  value="2.979933439782622e-05" />
   <inertia  izz="5.473347134294612e-11"  ixz="0.0"  ixy="0.0"  ixx="5.473347134294612e-11"  iyy="5.473347134294612e-11"  iyz="0.0" />
  </inertial>
 </link>
 <link  name="L6" >
  <visual >
   <origin  xyz="0.0 0.0 0.0375"  rpy="0.0 0.0 0.0" />
   <geometry >
    <box  size="0.04 0.04 0.03499999999999997" />
   </geometry>
   <material  name="L6_Material" >
    <color  rgba="0.01568627450980392 0.5058823529411764 0.29411764705882354 1.0" />
   </material>
  </visual>
  <collision  name="L6_Collision" >
   <origin  xyz="0.0 0.0 0.0375"  rpy="0.0 0.0 0.0" />
   <geometry >
    <box  size="0.04 0.04 0.03499999999999997" />
   </geometry>
  </collision>
  <inertial >
   <origin  xyz="0.0 0.0 0.0375"  rpy="0.0 0.0 0.0" />
   <mass  value="0.04048799999999997" />
   <inertia  izz="1.0796799999999991e-05"  ixz="0.0"  ixy="0.0"  ixx="9.531549999999985e-06"  iyy="9.531549999999985e-06"  iyz="0.0" />
  </inertial>
 </link>
 <link  name="L5" >
  <visual >
   <origin  xyz="-0.0 0.0 0.13766"  rpy="0.0 0.0 0.0" />
   <geometry >
    <box  size="0.04 0.04 0.23532199784979038" />
   </geometry>
   <material  name="L5_Material" >
    <color  rgba="0.0 0.6627450980392157 0.3607843137254902 1.0" />
   </material>
  </visual>
  <collision  name="L5_Collision" >
   <origin  xyz="-0.0 0.0 0.13766"  rpy="0.0 0.0 0.0" />
   <geometry >
    <box  size="0.04 0.04 0.23532199784979038" />
   </geometry>
  </collision>
  <inertial >
   <origin  xyz="-0.0 0.0 0.13766"  rpy="0.0 0.0 0.0" />
   <mass  value="0.2722204871126375" />
   <inertia  izz="7.259212989670334e-05"  ixz="0.0"  ixy="0.0"  ixx="0.001292512914843472"  iyy="0.001292512914843472"  iyz="0.0" />
  </inertial>
 </link>
 <joint  type="revolute"  name="Main_ground" >
  <parent  link="G" />
  <child  link="L3" />
  <origin  xyz="0.0 0.0 0.0"  rpy="3.141592653589793 0.12102721980920506 3.141592653589793" />
  <axis  xyz="0 1 0" />
  <limit  lower="-3.141592653589793"  effort="10.2"  upper="3.141592653589793"  velocity="23.99988291783386" />
  <dynamics  friction="0"  damping="0.05" />
 </joint>
 <joint  type="fixed"  name="Main_ground_G_WeldActuator" >
  <parent  link="G" />
  <child  link="Main_ground_GActuator" />
  <origin  xyz="0.0 0.03999999955296517 0.0"  rpy="-1.570796326794897 0.12102721980920506 3.1415926535897927" />
 </joint>
 <link  name="Main_ground_GActuator" >
  <visual >
   <geometry >
    <cylinder  length="0.04"  radius="0.048" />
   </geometry>
   <material  name="Main_ground_GActuator_Material" >
    <color  rgba="0.1568627450980392 0.42745098039215684 0.8 0.9" />
   </material>
  </visual>
  <inertial >
   <inertia  izz="0.01056"  ixz="0.0"  ixy="0.0"  ixx="0.0067466666666666664"  iyy="0.0067466666666666664"  iyz="0.0" />
   <mass  value="0.44" />
  </inertial>
 </link>
 <link  name="Main_ground_GUnit" >
  <visual >
   <geometry >
    <cylinder  length="0.03999999910593033"  radius="0.019999999552965164" />
   </geometry>
   <material  name="Main_ground_GUnit_Material" >
    <color  rgba="0.1568627450980392 0.42745098039215684 0.8 0.9" />
   </material>
  </visual>
  <inertial >
   <inertia  izz="0.0009999999776482583"  ixz="0.0"  ixy="0.0"  ixx="0.0008333333147068819"  iyy="0.0008333333147068819"  iyz="0.0" />
   <mass  value="0.1" />
  </inertial>
 </link>
 <joint  type="fixed"  name="Main_ground_G_WeldUnit" >
  <parent  link="G" />
  <child  link="Main_ground_GUnit" />
  <origin  xyz="0.0 0.0 0.0"  rpy="-1.570796326794897 0.12102721980920506 3.1415926535897927" />
 </joint>
 <joint  type="revolute"  name="Main_knee" >
  <parent  link="L3" />
  <child  link="L4" />
  <origin  xyz="-1.6079280025885e-17 0.0 0.3727264412407577"  rpy="0.0 0.3142387036570107 0.0" />
  <axis  xyz="0 1 0" />
  <limit  lower="-3.141592653589793"  effort="600.0"  upper="3.141592653589793"  velocity="6.283185307179586" />
  <dynamics  friction="0"  damping="0.05" />
 </joint>
 <link  name="Main_knee_L3Unit" >
  <visual >
   <geometry >
    <cylinder  length="0.03"  radius="0.016" />
   </geometry>
   <material  name="Main_knee_L3Unit_Material" >
    <color  rgba="0.37254901960784315 0.5019607843137255 0.8352941176470589 0.9" />
   </material>
  </visual>
  <inertial >
   <inertia  izz="0.0008"  ixz="0.0"  ixy="0.0"  ixx="0.00065"  iyy="0.00065"  iyz="0.0" />
   <mass  value="0.1" />
  </inertial>
 </link>
 <joint  type="fixed"  name="Main_knee_L3_WeldUnit" >
  <parent  link="L3" />
  <child  link="Main_knee_L3Unit" />
  <origin  xyz="-1.6079280025885e-17 0.0 0.3727264412407577"  rpy="1.5707963267948966 0.3142387036570107 -1.1102230246251565e-16" />
 </joint>
 <joint  type="fixed"  name="Main_ee" >
  <parent  link="L4" />
  <child  link="EE" />
  <origin  xyz="4.163336342344337e-17 0.0 0.23436083290515936"  rpy="3.141592653589793 0.19321148384780562 3.141592653589793" />
 </joint>
 <link  name="Main_ee_L4Unit" >
  <visual >
   <geometry >
    <cylinder  length="0.03"  radius="0.016" />
   </geometry>
   <material  name="Main_ee_L4Unit_Material" >
    <color  rgba="0.5176470588235295 0.5843137254901961 0.8705882352941177 0.9" />
   </material>
  </visual>
  <inertial >
   <inertia  izz="0.0008"  ixz="0.0"  ixy="0.0"  ixx="0.00065"  iyy="0.00065"  iyz="0.0" />
   <mass  value="0.1" />
  </inertial>
 </link>
 <joint  type="fixed"  name="Main_ee_L4_WeldUnit" >
  <parent  link="L4" />
  <child  link="Main_ee_L4Unit" />
  <origin  xyz="4.163336342344337e-17 0.0 0.23436083290515936"  rpy="-1.5707963267948966 0.19321148384780584 -3.141592653589793" />
 </joint>
 <joint  type="revolute"  name="Main_connection_1" >
  <parent  link="L3" />
  <child  link="L6" />
  <origin  xyz="-0.06709075942333638 0.0 0.24227218680649248"  rpy="0.0 -1.4497691069856917 0.0" />
  <axis  xyz="0 1 0" />
  <limit  lower="-3.141592653589793"  effort="10.2"  upper="3.141592653589793"  velocity="23.99988291783386" />
  <dynamics  friction="0"  damping="0.05" />
 </joint>
 <joint  type="fixed"  name="Main_connection_1_L3_WeldActuator" >
  <parent  link="L3" />
  <child  link="Main_connection_1_L3Actuator" />
  <origin  xyz="-0.06709075942333638 0.03999999955296517 0.24227218680649248"  rpy="1.5707963267948966 -1.449769106985692 -1.1102230246251565e-16" />
 </joint>
 <link  name="Main_connection_1_L3Actuator" >
  <visual >
   <geometry >
    <cylinder  length="0.04"  radius="0.048" />
   </geometry>
   <material  name="Main_connection_1_L3Actuator_Material" >
    <color  rgba="0.37254901960784315 0.5019607843137255 0.8352941176470589 0.9" />
   </material>
  </visual>
  <inertial >
   <inertia  izz="0.01056"  ixz="0.0"  ixy="0.0"  ixx="0.0067466666666666664"  iyy="0.0067466666666666664"  iyz="0.0" />
   <mass  value="0.44" />
  </inertial>
 </link>
 <link  name="Main_connection_1_L3Unit" >
  <visual >
   <geometry >
    <cylinder  length="0.03999999910593033"  radius="0.019999999552965164" />
   </geometry>
   <material  name="Main_connection_1_L3Unit_Material" >
    <color  rgba="0.37254901960784315 0.5019607843137255 0.8352941176470589 0.9" />
   </material>
  </visual>
  <inertial >
   <inertia  izz="0.0009999999776482583"  ixz="0.0"  ixy="0.0"  ixx="0.0008333333147068819"  iyy="0.0008333333147068819"  iyz="0.0" />
   <mass  value="0.1" />
  </inertial>
 </link>
 <joint  type="fixed"  name="Main_connection_1_L3_WeldUnit" >
  <parent  link="L3" />
  <child  link="Main_connection_1_L3Unit" />
  <origin  xyz="-0.06709075942333638 0.0 0.24227218680649248"  rpy="1.5707963267948966 -1.449769106985692 -1.1102230246251565e-16" />
 </joint>
 <joint  type="revolute"  name="branch_1" >
  <parent  link="L6" />
  <child  link="L5" />
  <origin  xyz="0.0 0.0 0.07499999999999997"  rpy="3.141592653589793 1.0172020710109342 3.141592653589793" />
  <axis  xyz="0 1 0" />
  <limit  lower="-3.141592653589793"  effort="600.0"  upper="3.141592653589793"  velocity="6.283185307179586" />
  <dynamics  friction="0"  damping="0.05" />
 </joint>
 <link  name="branch_1_L6Unit" >
  <visual >
   <geometry >
    <cylinder  length="0.03"  radius="0.016" />
   </geometry>
   <material  name="branch_1_L6Unit_Material" >
    <color  rgba="0.01568627450980392 0.5058823529411764 0.29411764705882354 0.9" />
   </material>
  </visual>
  <inertial >
   <inertia  izz="0.0008"  ixz="0.0"  ixy="0.0"  ixx="0.00065"  iyy="0.00065"  iyz="0.0" />
   <mass  value="0.1" />
  </inertial>
 </link>
 <joint  type="fixed"  name="branch_1_L6_WeldUnit" >
  <parent  link="L6" />
  <child  link="branch_1_L6Unit" />
  <origin  xyz="0.0 0.0 0.07499999999999997"  rpy="-1.5707963267948966 1.0172020710109342 -3.141592653589793" />
 </joint>
 <link  name="Main_connection_2_L4Pseudo" >
  <visual >
   <geometry >
    <sphere  radius="0.02857142793280738" />
   </geometry>
   <material  name="Main_connection_2_L4Pseudo_Material" >
    <color  rgba="0.5176470588235295 0.5843137254901961 0.8705882352941177 0.5" />
   </material>
  </visual>
  <inertial >
   <mass  value="0.05" />
   <inertia  izz="1.632652988239212e-05"  ixz="0.0"  ixy="0.0"  ixx="1.632652988239212e-05"  iyy="1.632652988239212e-05"  iyz="0.0" />
  </inertial>
 </link>
 <joint  type="revolute"  name="Main_connection_2_L4_revolute" >
  <parent  link="L4" />
  <child  link="Main_connection_2_L4Pseudo" />
  <origin  xyz="2.7755575615628914e-17 0.0 0.09843154982016689"  rpy="3.141592653589793 0.19321148384780562 3.141592653589793" />
  <axis  xyz="0 1 0" />
  <limit  lower="-3.141592653589793"  effort="600.0"  upper="3.141592653589793"  velocity="6.283185307179586" />
  <dynamics  friction="0"  damping="0.05" />
 </joint>
 <joint  type="fixed"  name="Main_connection_2_L4_Weld" >
  <parent  link="L5" />
  <child  link="Main_connection_2_L5Pseudo" />
  <origin  xyz="-2.0816681711721685e-17 0.0 0.2753219978497904"  rpy="3.141592653589793 0.5535942557839628 3.141592653589793" />
 </joint>
 <link  name="Main_connection_2_L5Pseudo" >
  <visual >
   <geometry >
    <sphere  radius="0.028571428571428574" />
   </geometry>
   <material  name="Main_connection_2_L5Pseudo_Material" >
    <color  rgba="0.0 0.6627450980392157 0.3607843137254902 0.5" />
   </material>
  </visual>
  <inertial >
   <mass  value="0.05" />
   <inertia  izz="1.6326530612244903e-05"  ixz="0.0"  ixy="0.0"  ixx="1.6326530612244903e-05"  iyy="1.6326530612244903e-05"  iyz="0.0" />
  </inertial>
 </link>
</robot>
